Workbook

Sheet Đọc trước
A1: KẾ HOẠCH A/B TESTING PAGE TRUYỆN — ĐỌC TRƯỚC
A2: Mục tiêu: sau ~15 tuần biết Format, Hook và cách làm (AI vs Human) nào ra nhiều tiền nhất — và có đáng công không.
A4: Việc cần làm TRƯỚC khi bắt đầu
A5: 1. Biết app trả tiền theo gì (install / đăng ký / nạp xu), bao nhiêu mỗi lần, và link có SUB-ID để tách từng bài. Không có Sub-ID thì A/B test vô nghĩa.
A6: 2. Điền các ô GIẢ ĐỊNH trong sheet Cài đặt (tiền/install, giá giờ công, phút làm mỗi bài) bằng số thật của bạn.
A7: 3. Đọc sheet "A-B là gì" (5 phút) rồi thử "Máy tính A-B".
A9: Bản đồ các sheet
A10: Sheet | B10: Dùng để làm gì
A11: A-B là gì | B11: Giải thích dễ hiểu + ví dụ số.
A12: Cài đặt | B12: Các con số gốc: ngày bắt đầu, tiền, giờ công, ngưỡng, kết quả chốt sau mỗi thí nghiệm.
A13: Page và Ngách | B13: 6 page lõi (P1–P6) + 2 page mở rộng, tên gợi ý, hook mẫu, rủi ro, checklist tạo page.
A14: Thí nghiệm | B14: Thiết kế TN1–TN5, 7 quy tắc vàng, vì sao xếp bài luân phiên.
A15: Lịch 15 tuần | B15: Việc từng tuần, của AI và của Human, cổng để sang tuần sau.
A16: Prompt và Quy trình | B16: 3 prompt hook, 3 prompt theo format, quy trình AI 80%, checklist Human 20%.
A17: Nhật ký bài | B17: HÀNG NGÀY: 840 bài đã xếp sẵn Format/Hook/Cách làm/Giờ/Sub-ID; bạn chỉ nhập số liệu.
A18: Kết quả | B18: Tự tính CTR, p-value, $/1.000 reach, lãi ròng/bài, "có xứng đáng không?", so sánh ngách.
A19: Cỡ mẫu | B19: Cần bao nhiêu bài/tuần để đủ kết luận; vì sao TN3 cần chạy lâu hơn khi Human chỉ 20%.
A20: Máy tính A-B | B20: Dán 2 con số mỗi bên → biết khác thật hay do may rủi.
A21: Sức khỏe Page | B21: Hàng tuần: follower, reach, cảnh báo reach tụt.
A23: Quy ước màu
A24: Nền vàng, chữ xanh dương | B24: Ô BẠN nhập (số liệu, giả định).
A25: Chữ đen | B25: Công thức tự tính — đừng sửa tay.
A26: Chữ xanh lá | B26: Giá trị lấy từ sheet khác (vd Cài đặt).
A27: Dòng xám nghiêng | B27: Dòng VÍ DỤ, không tính vào kết quả.
A29: Vòng lặp hằng ngày / hằng tuần
A30: Hằng ngày: lọc Nhật ký bài theo "Ngày đăng" = hôm nay → làm đúng Format/Hook/Cách làm của các dòng đó → đăng + link Sub-ID (cột L).
A31: Sau 48 giờ: nhập Reach / Clicks / Installs (cột O, P, Q) cho các bài cũ.
A32: Hằng tuần: ghi Sức khỏe Page; Human ghi 3 dòng "học được gì".
A33: Ngày cuối mỗi thí nghiệm: mở Kết quả → chốt người thắng → nhập vào Cài đặt (B32/B33).
A34: Trong lúc thí nghiệm chạy: KHÔNG kết luận, KHÔNG đổi gì.
A36: Lưu ý trung thực
A37: Các con số trong Cài đặt (tiền/install = $1, CTR 1%, reach 500, giờ công $5, phút làm bài) là GIẢ ĐỊNH để file chạy được, không phải số liệu thật. Thay bằng số của bạn.
A38: Mình hiểu "80% AI / 20% Human" là: 80% bài do AI làm trọn, 20% bài có người nghiên cứu trend trước. Nếu bạn muốn hiểu khác, báo để chỉnh.
A39: Lịch dài 15 tuần (không phải 90 ngày như kế hoạch trước) vì mỗi thí nghiệm cần đủ mẫu và chạy lần lượt. Trong lúc test, các bài vẫn có link nên vẫn có thể ra tiền.
A40: Meta có thể thay đổi giới hạn link và luật nội dung không gốc. Nếu reach tụt, xem sheet Sức khỏe Page và giảm số bài có link.

Sheet A-B là gì
A1: A/B TESTING LÀ GÌ? — giải thích cho người chưa từng làm
A2: Đọc 5 phút trước khi bắt đầu. Có ví dụ số dùng được trong sheet "Máy tính A-B".
A4: Khái niệm | B4: Giải thích
A5: A/B testing là gì? | B5: So sánh 2 hay nhiều phiên bản chỉ khác nhau MỘT thứ (vd Reel vs Carousel), đăng trong cùng điều kiện, rồi dùng số liệu (click, install, tiền) để biết phiên bản nào tốt hơn — thay vì dựa cảm giác.
A6: Vì sao cần? | B6: Cảm giác "Reel chắc ăn hơn" có thể sai. Mỗi bài có yếu tố may rủi (giờ đăng, ngày trong tuần, thuật toán). A/B xếp để may rủi chia đều cho mọi phiên bản, nhờ đó chênh lệch còn lại mới đáng tin.
A7: Mốc (baseline) và biến thể | B7: Baseline = phiên bản bạn đang so sánh với (ở đây: Ảnh chữ, Prompt A, AI tự động). Biến thể = các phiên bản còn lại. Câu hỏi luôn là: biến thể có hơn mốc đủ nhiều và đủ chắc không?
A8: Reach / Click / CTR | B8: Reach = số người thấy bài. Click = số người bấm link. CTR = Click ÷ Reach. Ví dụ 12.000 reach, 150 click → CTR 1,25%.
A9: Click→Install và $/1.000 reach | B9: Click→Install = số người cài app ÷ số click. $/1.000 reach = doanh thu ÷ reach × 1.000: chỉ số gần "tiền" nhất, so sánh công bằng giữa các biến thể có reach khác nhau.
A10: p-value (nói đơn giản) | B10: Nếu thực ra hai phiên bản BẰNG NHAU, p-value là xác suất vẫn thấy chênh lệch lớn như vậy chỉ do may rủi. p < 0,05 → đủ tin là khác thật. p ≥ 0,05 → chưa phân biệt được: coi là HÒA.
A11: Cỡ mẫu | B11: Càng ít dữ liệu càng dễ nhầm. Quy tắc tối thiểu: mỗi phiên bản ≥ 30 click và ≥ 30 bài. Muốn biết chính xác cần bao nhiêu → sheet "Cỡ mẫu".
A12: Ví dụ số 1 (khác thật) | B12: Reel: 12.000 reach, 150 click (CTR 1,25%). Carousel: 12.000 reach, 110 click (0,92%). Chênh 36% và p ≈ 0,013 < 0,05 → Reel thắng thật. (Điền vào "Máy tính A-B".)
A13: Ví dụ số 2 (chưa chắc) | B13: A: 3.000 reach, 30 click (1,00%). B: 3.000 reach, 36 click (1,20%). Chênh 20% nhưng p ≈ 0,46 → HÒA, vì quá ít dữ liệu. Đừng chọn B chỉ vì con số lớn hơn.
A14: Vì sao làm lần lượt? | B14: TN1 (Format) → TN2 (Hook) → TN3 (AI vs Human). Mỗi thí nghiệm khóa kết quả của thí nghiệm trước. Đổi nhiều thứ cùng lúc thì không biết cái nào có tác dụng.
A15: Làm sao biết đáng công hay không? | B15: Không chỉ xem ai nhiều tiền hơn. Lãi ròng/bài = doanh thu/bài − (phút làm ÷ 60 × giá giờ công). Phiên bản tốn công hơn chỉ "xứng đáng" nếu lãi ròng vẫn cao hơn mốc. Xem bảng "Công sức có xứng đáng?" trong sheet Kết quả.
... A17: Giới hạn trung thực | B17: Facebook phân phối bài theo thuật toán nên số liệu có nhiễu; page mới reach thấp; các bài trong cùng page tương quan với nhau. File đã bù bằng luân phiên, hệ số an toàn 1,3 và ngưỡng 30/30, nhưng kết quả vẫn là xác suất, không phải chắc chắn tuyệt đối.

Sheet Cài đặt
A1: CÀI ĐẶT — các con số gốc của toàn bộ file
A2: Chữ XANH DƯƠNG + nền vàng = ô bạn được sửa. Mọi sheet khác tự tính theo các ô này.
A4: A. Thông tin chung
A5: Ngày bắt đầu Tuần 1 (nên là thứ Hai) | B5: 46307 | D5: Mọi mốc ngày trong file tính từ ô này. Đổi ô này nếu bạn bắt đầu muộn hơn.
A6: Số bài TEST có link / page / ngày | B6: 2 | D6: KHÔNG ĐỔI: Nhật ký bài đã được sinh sẵn cho 2 bài/ngày/page. Thêm 1 bài không link/ngày để giữ page "sống".
A7: Khung giờ đăng 1 (S1) | B7: 12:00 | D7: Giờ theo múi giờ KHÁN GIẢ MỤC TIÊU. Xem Page Insights để chỉnh sau.
A8: Khung giờ đăng 2 (S2) | B8: 20:00 | D8: Hai khung giờ được luân phiên đều giữa các biến thể để không biến thể nào có lợi thế giờ.
A9: Tỉ lệ bài Human mục tiêu khi vận hành thường | B9: 0.2 | D9: Thông tin: 80% AI tự động / 20% Human. Thí nghiệm 3 sinh sẵn 11/56 bài mỗi page ≈ 19,6%.
A11: B. Giả định về tiền — THAY BẰNG SỐ THẬT từ app của bạn
A12: Tiền thưởng cho mỗi install ($) | B12: 1 | D12: GIẢ ĐỊNH, chưa có nguồn. Lấy từ điều khoản đối tác của app. Nếu app trả theo đăng ký/nạp xu, nhập tiền trung bình quy đổi hoặc nhập "Doanh thu thực" ở Nhật ký bài.
A13: CTR giả định (click ÷ reach) | B13: 0.01 | D13: GIẢ ĐỊNH, chỉ dùng cho sheet Cỡ mẫu. Sau Tuần 7 thay bằng CTR thực tế từ Kết quả.
A14: Tỉ lệ click → install giả định | B14: 0.1 | D14: GIẢ ĐỊNH, chỉ để tham khảo. Số thực lấy từ cột "Click→Install" trong Kết quả.
A15: Reach trung bình mỗi bài giả định | B15: 500 | D15: GIẢ ĐỊNH cho page mới; dùng ở sheet Cỡ mẫu. Thay bằng số thật sau warm-up.
A16: Giá trị 1 giờ công của bạn/nhân sự ($/giờ) | B16: 5 | D16: GIẢ ĐỊNH. Dùng để tính "công sức có xứng đáng không". Nhập mức bạn thực sự trả hoặc coi là hợp lý.
A18: C. Thời gian làm 1 bài (phút) — ƯỚC TÍNH, sửa theo thực tế
A19: Định dạng | B19: AI tự động (phút) | C19: Human nghiên cứu (phút) | D19: Ghi chú
A20: Ảnh chữ | B20: 2 | C20: 15 | D20: AI tự động = người chỉ duyệt nhanh, KHÔNG nghiên cứu. Human = nghiên cứu trend + viết góc nhìn riêng + chỉnh sửa.
A21: Carousel | B21: 4 | C21: 25 | D21: Carousel 6 slide.
A22: Reel | B22: 8 | C22: 40 | D22: Reel 15 giây có chữ/voiceover.
A24: D. Ngưỡng quyết định (đừng đổi giữa chừng)
A25: Số click tối thiểu mỗi biến thể mới được kết luận | B25: 30 | D25: Dưới ngưỡng này kết quả chủ yếu là may rủi.
A26: Số bài tối thiểu mỗi biến thể mới được kết luận | B26: 30 | D26: Đảm bảo kết quả không đến từ 1–2 bài "trúng".
A27: Ngưỡng p-value (mức "có ý nghĩa") | B27: 0.05 | D27: p < 0,05 nghĩa là: nếu thực ra hai bên bằng nhau thì chỉ có <5% khả năng thấy chênh lệch lớn thế này do may rủi.
A28: Chênh lệch tối thiểu đáng quan tâm (lift) | B28: 0.3 | D28: Dùng ở Cỡ mẫu: chỉ cố phát hiện biến thể tốt hơn mốc ít nhất 30%. Chênh nhỏ hơn thì cần nhiều bài hơn nhiều và thường không đáng công — kết quả sẽ hiện là HÒA.
A29: Độ nhạy mong muốn (power) | B29: 0.8 | D29: 80% = nếu chênh lệch thật ≥ lift, bạn có 80% khả năng phát hiện ra.
A31: E. Kết quả bạn CHỐT sau mỗi thí nghiệm (nhập tay)
A32: Format thắng (sau Thí nghiệm 1, cuối Tuần 7) | B32: Carousel | D32: Đang là giá trị TẠM để Thí nghiệm 2–3 có dữ liệu mẫu. Sau Tuần 7 chọn theo sheet Kết quả. Chọn từ danh sách.
A33: Hook thắng (sau Thí nghiệm 2, cuối Tuần 10) | B33: A | D33: Đang là giá trị TẠM. Sau Tuần 10 chọn theo sheet Kết quả.
A35: F. Mốc thời gian (tự tính từ ngày bắt đầu)
A36: Bắt đầu warm-up (Tuần 2) | B36: =$B$5+7 -> 46314 | D36: Tự tính
A37: Bắt đầu Thí nghiệm 1 — Format (Tuần 5) | B37: =$B$5+28 -> 46335 | D37: Tự tính
A38: Bắt đầu Thí nghiệm 2 — Hook (Tuần 8) | B38: =$B$5+49 -> 46356 | D38: Tự tính
A39: Bắt đầu Thí nghiệm 3 — AI vs Human (Tuần 11) | B39: =$B$5+70 -> 46377 | D39: Tự tính
A40: Chốt & mở rộng (Tuần 15) | B40: =$B$5+98 -> 46405 | D40: Tự tính

Sheet Page và Ngách
A1: PAGE VÀ NGÁCH — 6 page lõi để chạy thí nghiệm + 2 page mở rộng
A2: Mỗi page = 1 ngách. Tên là GỢI Ý: tự kiểm tra tên còn trống trên Facebook và không trùng nhãn hiệu/tên truyện đang có bản quyền.
A4: Page | B4: Ngách | C4: Tropes chính (3 hướng nội dung) | D4: Tên gợi ý 1 | E4: Tên gợi ý 2 | F4: Khán giả / lý do chọn | G4: Hook mẫu (tiếng Anh, tự viết — dùng để chạy thử prompt) | H4: Rủi ro nội dung | I4: Giai đoạn | J4: Tên page thật (bạn nhập) | K4: Link page (bạn nhập)
A5: P1 | B5: Werewolf / Rejected mate | C5: Rejected mate; Fated/True mate; Alpha & Luna | D5: Moonbound Mates | E5: Rejected Mate Chronicles | F5: Cộng đồng đông, gắn bó mạnh; app truyện đều quảng bá werewolf/alpha làm trụ cột. | G5: My mate rejected me in front of the whole pack. Then the Alpha King stepped forward and said one word: "Mine." | H5: Trung bình | I5: Lõi
A6: P2 | B6: Secret billionaire / CEO | C6: Hidden identity; CEO & assistant; billionaire's secret heir | D6: The Hidden Billionaire Club | E6: CEO Secrets Romance | F6: Kịch tính dễ hiểu, không cần biết bối cảnh trước. Hợp với ảnh chữ và carousel. | G6: She cleaned his office for a year. He never noticed she owned the building. | H6: Thấp | I6: Lõi
A7: P3 | B7: Contract marriage / Fake relationship | C7: Fake marriage; marriage of convenience; "rules of the contract" | D7: Contract Marriage Diaries | E7: Fake Vows Stories | F7: Hook một câu là hiểu ngay; trope phổ biến trên nhiều app truyện. | G7: Clause 7 of our contract: no falling in love. He has already broken it. | H7: Thấp | I7: Lõi
A8: P4 | B8: Revenge / Betrayal ("you'll regret it") | C8: Cheating ex returns; wronged heiress; glow-up revenge | D8: Sweet Revenge Romance | E8: Regret Him Later | F8: Hook cảm xúc mạnh, dễ gây comment ("Team nào?"). | G8: They laughed when I left with nothing. Five years later, they are begging me for a meeting. | H8: Thấp | I8: Lõi
A9: P5 | B9: Mafia / Dark romance (teaser PG-13) | C9: Mafia boss; enemies-to-lovers; protective hero | D9: Mafia Heart Stories | E9: Dangerous Love Tales | F9: Nhóm trung thành nhưng nội dung nhạy cảm: chỉ đăng teaser an toàn để khỏi bị hạn chế/chặn quảng cáo. | G9: The boss warned everyone: touch her and you die. She never imagined he meant it. | H9: Cao | I9: Lõi
A10: P6 | B10: Second chance / Secret baby | C10: Secret baby; second chance; ex returns | D10: Second Chance Hearts | E10: Secret Baby Secrets | F10: Cảm xúc gia đình + hối hận, hook dễ viết, nhóm đọc trung thành. | G10: He found out about our daughter five years too late. | H10: Thấp | I10: Lõi
A11: P7 | B11: Vampire / Royal / Historical | C11: Vampire mate; duke & governess; royal secret | D11: Fated Fangs | E11: Royal Secrets Romance | F11: Khán giả khác biệt. Chỉ mở sau Thí nghiệm 1 nếu còn công sức; KHÔNG nằm trong Nhật ký bài. | G11: The vampire king has waited three hundred years for one human heartbeat. Hers. | H11: Trung bình | I11: Mở rộng
A12: P8 | B12: Xianxia / Cultivation / LitRPG | C12: Reborn cultivator; system rewards; overpowered MC | D12: Reborn Cultivator Tales | E12: System Rewards Stories | F12: Khán giả thiên nam giới, khác hẳn romance — thử như thí nghiệm riêng sau Tuần 15. | G12: Thấp | H12: Mở rộng
A14: Checklist tạo mỗi page (làm trong Tuần 1)
A15: 1. Tạo trong cùng một Business Portfolio, bật xác thực 2 bước (2FA) cho mọi quản trị viên. Không mua page.
A16: 2. Ảnh đại diện + ảnh bìa riêng cho từng page (tự tạo hoặc ảnh có giấy phép). Không dùng bìa/ảnh của truyện có bản quyền.
A17: 3. Mô tả ngắn: ngách + "stories & teasers". KHÔNG đặt tên app trong tên page; ghi rõ là page giới thiệu truyện.
A18: 4. Mỗi page có "giọng" khác nhau (cách xưng hô, emoji, kiểu hook) để không giống hệt nhau (tránh bị coi là spam/nội dung lặp).
A19: 5. Cột "Page" (P1–P6) dùng làm mã trong Sub-ID và Nhật ký bài — đừng đổi mã.
A20: 6. Chỉ P1–P6 có trong Nhật ký bài. P7–P8 chỉ mở sau khi có kết quả Thí nghiệm 1.

Sheet Thí nghiệm
A1: THIẾT KẾ THÍ NGHIỆM — làm TUẦN TỰ, mỗi lần chỉ đổi MỘT thứ
A2: Vì sao tuần tự? Nếu đổi format, hook và cách làm cùng lúc thì không biết cái nào tạo ra khác biệt.
A4: Mã | B4: Câu hỏi cần trả lời | C4: Biến thay đổi | D4: Các phiên bản | E4: Giữ CỐ ĐỊNH | F4: Thời gian | G4: Số bài | H4: Chỉ số quyết định | I4: Quy tắc chốt | J4: Kết quả dùng cho
A5: TN1 | B5: Format nào kéo nhiều click/tiền nhất, và có đáng công làm hơn không? | C5: Định dạng bài | D5: Ảnh chữ (mốc) · Carousel · Reel | E5: Hook = Prompt A; cách làm = AI tự động; cùng 6 page; 2 khung giờ luân phiên đều | F5: Tuần 5–7 (21 ngày) | G5: 252 bài (42 bài/page, mỗi format 14 bài/page = 84 bài/format) | H5: CTR, Click→Install, $/1.000 reach, rồi lãi ròng/bài sau trừ công | I5: Chỉ chốt vào ngày cuối Tuần 7 khi mỗi format ≥ 30 click & ≥ 30 bài. p < 0,05 và lãi ròng/bài hơn mốc → chọn. Nếu hòa → chọn format rẻ công hơn. | J5: Nhập "Format thắng" vào Cài đặt B32 → TN2, TN3 tự dùng format đó
A6: TN2 | B6: Prompt hook nào (A/B/C) cho nhiều click nhất? | C6: Prompt tạo hook | D6: Prompt A (mốc) · Prompt B · Prompt C (xem sheet Prompt và Quy trình) | E6: Format = thắng của TN1; cách làm = AI tự động; cùng page, khung giờ luân phiên | F6: Tuần 8–10 (21 ngày) | G6: 252 bài (mỗi hook 84 bài) | H6: CTR, $/1.000 reach | I6: Giống TN1. Chi phí công như nhau nên chỉ cần xem tiền/click. Hòa → chọn hook ra ít chỉnh sửa nhất. | J6: Nhập "Hook thắng" vào Cài đặt B33 → TN3 dùng hook đó
A7: TN3 | B7: Phần bài Human nghiên cứu (20%) có kiếm nhiều hơn đủ bù giờ công không? | C7: Cách làm | D7: AI tự động 80% (mốc) · Human nghiên cứu 20% | E7: Format + Hook = thắng của TN1/TN2; cùng page; Human trải đều theo tuần và 2 khung giờ | F7: Tuần 11–14 (28 ngày) | G7: 336 bài (270 AI + 66 Human) | H7: Lãi ròng/bài = doanh thu/bài − công/bài | I7: Chỉ chốt cuối Tuần 14. Nếu Human không đủ mẫu: tạm tăng lên 1/3 (xem Cỡ mẫu). Xứng đáng nếu lãi ròng/bài Human > AI và p < 0,05. | J7: Quyết định giữ/nâng/giảm tỉ lệ Human khi vận hành
A8: TN4 (tùy chọn) | B8: Link đặt trong comment hay trong bài thì ít bị giảm reach hơn? | C8: Vị trí link | D8: Link trong comment đầu · link trong bài · link ở bio/mô tả | E8: Mọi thứ khác theo kết quả TN1–3 | F8: Sau Tuần 15 | G8: Tự thiết kế, ≥ 30 click/biến thể | H8: Reach TB + CTR | I8: Chạy khi đã chốt TN1–3 và thấy reach tụt sau khi rải link. | J8: Quy tắc đặt link
A9: TN5 (tùy chọn) | B9: Ngách nào đáng nhân bản? | C9: Ngách / page | D9: P1–P6 | E9: Không phải A/B chặt vì mỗi page khác tuổi/follower | F9: Liên tục | G9: Dữ liệu sẵn trong Kết quả | H9: $ / 1.000 reach theo page | I9: Xem bảng "So sánh ngách" cuối sheet Kết quả. Cắt page đứng cuối nếu 2 lần liên tiếp thấp nhất, nhân đôi ngách đứng đầu. | J9: Mở thêm page cùng ngách, hoặc P7–P8
A11: A/B testing — 7 quy tắc vàng cho người mới
A12: 1. MỘT biến mỗi lần. Đổi 2 thứ cùng lúc là không biết thứ nào có tác dụng.
A13: 2. ĐỪNG xem kết quả giữa chừng để đổi ý. Nhìn sớm rất dễ thấy "người thắng" chỉ là may rủi. Chỉ chốt ở ngày cuối thí nghiệm.
A14: 3. CÙNG điều kiện: cùng page, cùng hook (hoặc cùng biến đã cố định), các khung giờ/ngày trong tuần luân phiên đều — Nhật ký bài đã làm sẵn việc này.
A15: 4. ĐỦ mẫu: mỗi biến thể ≥ 30 click và ≥ 30 bài trước khi kết luận (xem Cỡ mẫu).
A16: 5. Mỗi bài có SUB-ID RIÊNG để biết tiền đến từ biến thể nào (cột L trong Nhật ký bài, ví dụ P1_EXP1_R_A_AI_001).
A17: 6. Quyết định theo TIỀN, không theo "thích": CTR cao nhưng không ra install thì vẫn thua. Sau cùng luôn trừ công sức.
A18: 7. Ghi lại cả những gì thất bại (cột Story/ý tưởng + ghi chú). Thí nghiệm hòa cũng là kết quả hữu ích: chọn cách rẻ công hơn.
A20: Vì sao bài được xếp luân phiên (không chọn tay)?
A21: Nếu bạn tự chọn bài nào làm Reel, bạn sẽ vô thức dồn ý tưởng hay vào Reel → Reel "thắng" vì ý tưởng, không phải vì format.
A22: Nhật ký bài xoay vòng 3 phiên bản qua 2 khung giờ × 7 ngày trong tuần (chu kỳ 21 ngày) → mỗi phiên bản rơi đúng 7 lần vào mỗi khung giờ của mỗi page.
A23: AI sinh nội dung độc lập cho từng dòng, bạn chỉ làm theo ô "Format/Hook/Cách làm" ghi sẵn ở dòng đó.

Sheet Lịch 15 tuần
A1: LỊCH 15 TUẦN — làm theo từng dòng
A2: Ngày tự tính từ Cài đặt B5. Trong tuần thí nghiệm: cuối tuần chỉ NHẬP số liệu, không kết luận, không đổi gì.
A4: Tuần | B4: Từ ngày | C4: Đến ngày | D4: Giai đoạn | E4: Mục tiêu | F4: Bài/page/ngày | G4: Có link? | H4: Việc của AI (80% tự động) | I4: Việc của Human (20%) | J4: Số liệu cần ghi cuối tuần | K4: Điều kiện để sang tuần sau
A5: 1 | B5: ='Cài đặt'!$B$5+7*(A5-1) -> 46307 | C5: =B5+6 -> 46313 | D5: Chuẩn bị | E5: Dựng hạ tầng, chưa đăng bài thật | F5: 0 | G5: Không | H5: Tạo template ảnh/carousel/reel; chạy thử 3 prompt hook trên 6 ngách; dựng quy trình tạo + lên lịch tự động. | I5: Tạo Business Portfolio + 2FA; tạo 6 page; xin link tracking CÓ Sub-ID từ app; click thử để thấy Sub-ID trong dashboard; điền Cài đặt (tiền/install, giờ công thật). | J5: Không | K5: Click thử link ra đúng Sub-ID trong dashboard; 6 page hoàn thiện avatar/cover/bio.
A6: 2 | B6: ='Cài đặt'!$B$5+7*(A6-1) -> 46314 | C6: =B6+6 -> 46320 | D6: Warm-up | E6: Page có hoạt động đều, follower thật | F6: 2–3 | G6: KHÔNG | H6: Sinh bài từ prompt: câu hỏi tương tác, trích dẫn trope, meme; xoay đều 3 format; lên lịch qua Meta Business Suite; lưu mẫu hook/prompt hiệu quả. | I6: Trả lời comment; 2–3 giờ xem trend (top chart app truyện, trope đang hot trên Reels/BookTok, phim ngắn đang hot) và ghi vào danh sách "trope hot" (xem sheet Prompt và Quy trình). | J6: Follower, reach TB mỗi page (sheet Sức khỏe Page) | K6: Đăng đều mỗi ngày, không bị hạn chế.
A7: 3 | B7: ='Cài đặt'!$B$5+7*(A7-1) -> 46321 | C7: =B7+6 -> 46327 | D7: Warm-up | E7: Page có hoạt động đều, follower thật | F7: 2–3 | G7: KHÔNG | H7: Sinh bài từ prompt: câu hỏi tương tác, trích dẫn trope, meme; xoay đều 3 format; lên lịch qua Meta Business Suite; lưu mẫu hook/prompt hiệu quả. | I7: Trả lời comment; 2–3 giờ xem trend (top chart app truyện, trope đang hot trên Reels/BookTok, phim ngắn đang hot) và ghi vào danh sách "trope hot" (xem sheet Prompt và Quy trình). Chọn 3 trope sẽ dùng trong TN. | J7: Như tuần trước + reach theo format (tín hiệu sớm, chưa kết luận) | K7: Follower tăng đều.
A8: 4 | B8: ='Cài đặt'!$B$5+7*(A8-1) -> 46328 | C8: =B8+6 -> 46334 | D8: Warm-up | E8: Chốt trước khi test | F8: 2–3 | G8: KHÔNG | H8: Sinh bài từ prompt: câu hỏi tương tác, trích dẫn trope, meme; xoay đều 3 format; lên lịch qua Meta Business Suite; lưu mẫu hook/prompt hiệu quả. | I8: Trả lời comment; 2–3 giờ xem trend (top chart app truyện, trope đang hot trên Reels/BookTok, phim ngắn đang hot) và ghi vào danh sách "trope hot" (xem sheet Prompt và Quy trình). Kiểm tra lại Sub-ID, template, lịch đăng Tuần 5. | J8: Như tuần trước | K8: ≥ 500 follower thật/page, 21 ngày đăng đều, không cảnh báo hạn chế. Chưa đạt → kéo dài warm-up thêm 1 tuần.
A9: 5 | B9: ='Cài đặt'!$B$5+7*(A9-1) -> 46335 | C9: =B9+6 -> 46341 | D9: TN1 Format | E9: So Ảnh chữ vs Carousel vs Reel | F9: 3 (2 test + 1 thuần nội dung) | G9: Có — link trong comment đầu + Sub-ID | H9: Mỗi ngày làm 2 bài theo cột Format ghi trong Nhật ký bài (hook A, cách làm AI). Sinh bài, render, lên lịch, gắn link + Sub-ID. | I9: Duyệt nhanh ≤ 3 phút/bài; ghi lại cảm nhận thủ công chưa phải kết luận. | J9: Mỗi bài (sau 48 giờ): Reach, Clicks, Installs, Tương tác → Nhật ký bài. Hằng tuần: Sức khỏe Page. | K9: Chưa kết luận. Chỉ kiểm tra: bài đăng đúng format/giờ như lịch? Sub-ID ghi nhận click?
A10: 6 | B10: ='Cài đặt'!$B$5+7*(A10-1) -> 46342 | C10: =B10+6 -> 46348 | D10: TN1 Format | E10: So Ảnh chữ vs Carousel vs Reel | F10: 3 | G10: Có | H10: Như Tuần 5 | I10: Như Tuần 5 | J10: Như Tuần 5 | K10: Như Tuần 5. Không đổi gì giữa chừng.
A11: 7 | B11: ='Cài đặt'!$B$5+7*(A11-1) -> 46349 | C11: =B11+6 -> 46355 | D11: TN1 Format | E11: CHỐT thí nghiệm 1 | F11: 3 | G11: Có | H11: Như Tuần 5 | I11: Như Tuần 5. Cuối tuần: mở sheet Kết quả. | J11: Hoàn tất số liệu 252 bài | K11: Mỗi format ≥ 30 click & ≥ 30 bài. Nhập "Format thắng" vào Cài đặt B32. Chưa đủ → chạy thêm 1 tuần theo cùng lịch.
A12: 8 | B12: ='Cài đặt'!$B$5+7*(A12-1) -> 46356 | C12: =B12+6 -> 46362 | D12: TN2 Hook | E12: So Prompt A vs B vs C | F12: 3 | G12: Có | H12: Sinh bài theo cột Hook trong Nhật ký bài (format thắng, cách làm AI). | I12: Duyệt nhanh; không thêm nghiên cứu. | J12: Như TN1 | K12: Chưa kết luận.
A13: 9 | B13: ='Cài đặt'!$B$5+7*(A13-1) -> 46363 | C13: =B13+6 -> 46369 | D13: TN2 Hook | E13: So Prompt A vs B vs C | F13: 3 | G13: Có | H13: Như Tuần 8 | I13: Như Tuần 8 | J13: Như TN1 | K13: Không đổi gì giữa chừng.
A14: 10 | B14: ='Cài đặt'!$B$5+7*(A14-1) -> 46370 | C14: =B14+6 -> 46376 | D14: TN2 Hook | E14: CHỐT thí nghiệm 2 | F14: 3 | G14: Có | H14: Như Tuần 8 | I14: Cuối tuần: mở sheet Kết quả. | J14: Hoàn tất 252 bài | K14: Mỗi hook ≥ 30 click & ≥ 30 bài. Nhập "Hook thắng" vào Cài đặt B33.
A15: 11 | B15: ='Cài đặt'!$B$5+7*(A15-1) -> 46377 | C15: =B15+6 -> 46383 | D15: TN3 AI vs Human | E15: So AI tự động vs Human nghiên cứu | F15: 3 | G15: Có | H15: Làm 80% số bài theo cột "AI tự động" (hoàn toàn tự động, người duyệt ≤ 3 phút). | I15: Làm ~20% số bài theo cột "Human nghiên cứu": mỗi bài ghi nguồn cảm hứng + phút thực tế (cột M, T). | J15: Như TN1 + phút thực tế của bài Human | K15: Chưa kết luận.
A16: 12 | B16: ='Cài đặt'!$B$5+7*(A16-1) -> 46384 | C16: =B16+6 -> 46390 | D16: TN3 AI vs Human | E16: So AI tự động vs Human nghiên cứu | F16: 3 | G16: Có | H16: Như Tuần 11 | I16: Như Tuần 11 | J16: Như TN1 + phút | K16: Không đổi gì giữa chừng.
... A19: 15 | B19: ='Cài đặt'!$B$5+7*(A19-1) -> 46405 | C19: =B19+6 -> 46411 | D19: Chốt & mở rộng | E19: Đưa công thức thắng vào vận hành, mở rộng | F19: Theo công thức thắng | G19: Có | H19: Chạy 100% công thức thắng (format + hook + tỉ lệ Human); nhân bản template cho page mới. | I19: Họp 1 giờ: xem bảng So sánh ngách → cắt page cuối bảng, nhân đôi ngách đứng đầu; quyết định mở P7–P8 hoặc TN4. | J19: Bảng So sánh ngách | K19: Quyết định mở rộng/cắt giảm đã ghi lại.

Sheet Prompt và Quy trình
A1: PROMPT VÀ QUY TRÌNH — 3 prompt hook (A/B/C), 3 prompt theo format, quy trình AI 80% và checklist Human 20%
A2: Điền [GENRE], [PREMISE], [KEY SCENE] từ truyện thật. Hook luôn phải ĐÚNG với truyện — đừng hứa điều truyện không có.
A4: PROMPT A — Khoảng trống tò mò (mốc so sánh) | B4: You write Facebook hooks for a story page in the [GENRE] niche. Story premise: [PREMISE]. Key scene: [KEY SCENE]. Write 5 hooks, each 1–2 sentences, under 220 characters. Rules: open a question or tension, withhold the payoff, end mid-moment. Do not invent events that are not in the story. No emojis beyond one. End each with a short line inviting the reader to read what happens next.
A5: PROMPT B — Cảnh đối đầu / lời thoại | B5: You write Facebook hooks for a story page in the [GENRE] niche. Story premise: [PREMISE]. Key scene: [KEY SCENE]. Write 5 hooks that open directly on a line of dialogue or a confrontation (the most dramatic line of the scene), followed by one sentence of context. Under 220 characters. Keep it faithful to the actual story. Tone: intense, emotional, no spoilers of the final twist.
A6: PROMPT C — Đồng cảm + câu hỏi tương tác | B6: You write Facebook hooks for a story page in the [GENRE] niche. Story premise: [PREMISE]. Key scene: [KEY SCENE]. Write 5 hooks that speak directly to the reader ("You..."/"Imagine...") or ask a relatable question about the trope (e.g. "Would you forgive him?"). Under 220 characters. Make the reader pick a side in the comments, then point them to the full story. Stay faithful to the story.
A8: PROMPT REEL (15 giây) | B8: You write short vertical video scripts (15 seconds) for a Facebook Reel in the [GENRE] niche. On-screen hook for seconds 0–3: [HOOK from the prompt A/B/C winner]. Story premise: [PREMISE]. Key scene: [KEY SCENE]. Output: (1) on-screen text for 0–3s, 3–8s, 8–13s, 13–15s; (2) one voiceover sentence per segment; (3) a caption under 15 words; (4) a last frame with a cliffhanger line, then "Full story: link in comments". PG-13, faithful to the story, no ending spoilers.
A9: PROMPT CAROUSEL (6 slide) | B9: Create a 6-slide Facebook carousel for a story page in the [GENRE] niche. Hook: [HOOK]. Story premise: [PREMISE]. Key scene: [KEY SCENE]. Slide 1: the hook, max 12 words. Slides 2–5: one escalating moment each, max 20 words per slide. Slide 6: a cliffhanger plus "Read the full story: link in comments". Also write a caption under 20 words. PG-13, faithful to the story.
A10: PROMPT ẢNH CHỮ (1 ảnh) | B10: Create ONE image post for a story page in the [GENRE] niche. Hook: [HOOK]. Story premise: [PREMISE]. Output: overlay text max 18 words built from the hook; a 1-sentence caption that asks the reader to pick a side; and 3 background mood keywords. PG-13, faithful to the story.
A12: QUY TRÌNH AI TỰ ĐỘNG (80% bài)
A13: 1. Đọc dòng kế hoạch | B13: Lấy từ Nhật ký bài: Page → ngách, Format, Hook (prompt), Khung giờ. Không tự đổi.
A14: 2. AI viết hook/kịch bản | B14: Chạy prompt A/B/C theo cột Hook; với Reel/Carousel/Ảnh chữ chạy thêm prompt theo format. Chọn 1 trong 5 phương án (hoặc để quy tắc tự chọn: ngắn nhất ≤ 220 ký tự).
A15: 3. Kiểm tra tự động | B15: Quy tắc: đúng độ dài; không nội dung người lớn/bạo lực quá mức; không nhắc tên app; hook khớp premise (không bịa tình tiết).
A16: 4. Dựng hình | B16: Ảnh chữ/Carousel: dùng template cố định (vd tạo hàng loạt bằng công cụ thiết kế có Bulk Create). Reel: template video + chữ trên màn hình. Ảnh/video chân thực do AI tạo: kiểm tra yêu cầu gắn nhãn nội dung AI của Meta.
A17: 5. Lên lịch | B17: Lên lịch trong Meta Business Suite đúng Khung giờ (S1/S2) của dòng đó.
A18: 6. Link + Sub-ID | B18: Bình luận đầu tiên: link tracking có Sub-ID lấy từ cột L, kèm dòng công khai affiliate (vd "Affiliate link").
A19: 7. Thu số liệu sau 48 giờ | B19: Reach: Page Insights của bài. Clicks/Installs: dashboard đối tác của app, lọc theo Sub-ID. Nếu app không báo theo Sub-ID: dùng link rút gọn riêng cho mỗi bài.
A20: 8. Nhập Nhật ký bài | B20: Điền cột M→T. Người duyệt AI ≤ 3 phút/bài; KHÔNG tính là "Human nghiên cứu".
A22: CHECKLIST HUMAN NGHIÊN CỨU (20% bài)
A23: Nghiên cứu (2–3 giờ/tuần) | B23: Xem top chart các app truyện, trope đang hot trên Reels/BookTok, phim ngắn (short drama) đang hot. Ghi: tên trope, câu mở đầu gây chú ý, định dạng, VÌ SAO hot (1 dòng).
A24: Chọn 1 góc nhìn riêng | B24: Chọn trope/tình tiết hợp ngách của page. Tự viết "góc nhìn riêng" bằng lời của bạn rồi đưa AI làm bản nháp. Tự chỉnh hook cho đúng truyện.
A25: KHÔNG sao chép | B25: Không copy câu chữ, cảnh, ảnh/video của phim hay truyện khác. Chỉ học CẤU TRÚC (trope, nhịp, kiểu mở đầu). Meta đang phạt nội dung không gốc.
A26: Ghi nguồn + phút thực tế | B26: Cột M: nguồn cảm hứng (link) + lý do chọn. Cột T: số phút thực tế bạn bỏ ra — đây là dữ liệu quyết định "có xứng đáng" ở TN3.
A27: Học được gì (3 dòng/tuần) | B27: Cuối tuần ghi: (1) trope nào hot tuần này, (2) bài Human nào thắng/thua AI, (3) vì sao. Đây là thứ AI tự động chưa làm được.
A29: Hiểu "80% AI / 20% Human" trong file này: 80% bài do AI làm trọn (người chỉ duyệt nhanh); 20% bài có người nghiên cứu trend và viết góc nhìn riêng trước khi nhờ AI. Nếu bạn hiểu khác, nói lại để mình chỉnh.

Sheet Nhật ký bài
A1: NHẬT KÝ BÀI — mỗi dòng = 1 bài test. Bảng đã sinh sẵn lịch đăng cho 3 thí nghiệm (840 bài).
A2: Chỉ nhập vào các cột NỀN VÀNG (M→T). Cột khác tự tính. Mỗi ngày: lọc cột "Ngày đăng" = hôm nay → làm đúng Format/Hook/Cách làm ghi ở dòng đó.
A3: Mã bài | B3: Thí nghiệm | C3: Page | D3: Ngách | E3: Ngày thứ | F3: Ngày đăng | G3: Khung | H3: Giờ đăng | I3: Format | J3: Hook (prompt) | K3: Cách làm | L3: Sub-ID (gắn vào link) | M3: Story / ý tưởng (+ nguồn cảm hứng nếu là Human) | N3: Link bài FB | O3: Reach | P3: Link clicks | Q3: Installs | R3: Doanh thu thực ($) — nếu có | S3: Tương tác (react+cmt+share) | T3: Phút thực tế — nếu có | U3: CTR | V3: Click→Install | W3: Doanh thu tính ($) | X3: $ / 1.000 reach | Y3: Phút công dùng
A4: E1-P1-000 | B4: EXP1 | C4: P1 | D4: =INDEX('Page và Ngách'!$B$5:$B$10,MATCH(C4,'Page và Ngách'!$A$5:$A$10,0)) -> Werewolf / Rejected mate | E4: 1 | F4: ='Cài đặt'!$B$37+E4-1 -> 46335 | G4: S1 | H4: =IF(G4="S1",'Cài đặt'!$B$7,'Cài đặt'!$B$8) -> 12:00 | I4: Reel | J4: A | K4: AI tự động | L4: =C4&"_"&B4&"_"&IF(I4="Reel","R",IF(I4="Carousel","C","I"))&"_"&J4&"_"&IF(K4="AI tự động","AI","HU")&"_"&RIGHT(A4,3) -> P1_EXP1_R_A_AI_000 | M4: VÍ DỤ: "Rejected mate" — hook về cảnh bị từ chối trước bầy | N4: facebook.com/…/posts/123 | O4: 820 | P4: 11 | Q4: 1 | S4: 36 | T4: 3 | U4: =IF(O4>0,P4/O4,"") -> 0.013414634 | V4: =IF(P4>0,Q4/P4,"") -> 0.090909091 | W4: =IF(R4<>"",R4,Q4*'Cài đặt'!$B$12) -> 1 | X4: =IF(O4>0,W4/O4*1000,"") -> 1.2195122 | Y4: =IF(T4<>"",T4,INDEX('Cài đặt'!$B$20:$C$22,MATCH(I4,'Cài đặt'!$A$20:$A$22,0),IF(K4="AI tự động",1,2))) -> 3 | Z4: ← DÒNG VÍ DỤ, không tính vào kết quả
A5: E1-P1-001 | B5: EXP1 | C5: P1 | D5: =INDEX('Page và Ngách'!$B$5:$B$10,MATCH(C5,'Page và Ngách'!$A$5:$A$10,0)) -> Werewolf / Rejected mate | E5: 1 | F5: ='Cài đặt'!$B$37+E5-1 -> 46335 | G5: S1 | H5: =IF(G5="S1",'Cài đặt'!$B$7,'Cài đặt'!$B$8) -> 12:00 | I5: Ảnh chữ | J5: A | K5: AI tự động | L5: =C5&"_"&B5&"_"&IF(I5="Reel","R",IF(I5="Carousel","C","I"))&"_"&J5&"_"&IF(K5="AI tự động","AI","HU")&"_"&RIGHT(A5,3) -> P1_EXP1_I_A_AI_001 | U5: =IF(O5>0,P5/O5,"") | V5: =IF(P5>0,Q5/P5,"") | W5: =IF(R5<>"",R5,Q5*'Cài đặt'!$B$12) -> 0 | X5: =IF(O5>0,W5/O5*1000,"") | Y5: =IF(T5<>"",T5,INDEX('Cài đặt'!$B$20:$C$22,MATCH(I5,'Cài đặt'!$A$20:$A$22,0),IF(K5="AI tự động",1,2))) -> 2
A6: E1-P1-002 | B6: EXP1 | C6: P1 | D6: =INDEX('Page và Ngách'!$B$5:$B$10,MATCH(C6,'Page và Ngách'!$A$5:$A$10,0)) -> Werewolf / Rejected mate | E6: 1 | F6: ='Cài đặt'!$B$37+E6-1 -> 46335 | G6: S2 | H6: =IF(G6="S1",'Cài đặt'!$B$7,'Cài đặt'!$B$8) -> 20:00 | I6: Carousel | J6: A | K6: AI tự động | L6: =C6&"_"&B6&"_"&IF(I6="Reel","R",IF(I6="Carousel","C","I"))&"_"&J6&"_"&IF(K6="AI tự động","AI","HU")&"_"&RIGHT(A6,3) -> P1_EXP1_C_A_AI_002 | U6: =IF(O6>0,P6/O6,"") | V6: =IF(P6>0,Q6/P6,"") | W6: =IF(R6<>"",R6,Q6*'Cài đặt'!$B$12) -> 0 | X6: =IF(O6>0,W6/O6*1000,"") | Y6: =IF(T6<>"",T6,INDEX('Cài đặt'!$B$20:$C$22,MATCH(I6,'Cài đặt'!$A$20:$A$22,0),IF(K6="AI tự động",1,2))) -> 4
A7: E1-P2-001 | B7: EXP1 | C7: P2 | D7: =INDEX('Page và Ngách'!$B$5:$B$10,MATCH(C7,'Page và Ngách'!$A$5:$A$10,0)) -> Secret billionaire / CEO | E7: 1 | F7: ='Cài đặt'!$B$37+E7-1 -> 46335 | G7: S1 | H7: =IF(G7="S1",'Cài đặt'!$B$7,'Cài đặt'!$B$8) -> 12:00 | I7: Carousel | J7: A | K7: AI tự động | L7: =C7&"_"&B7&"_"&IF(I7="Reel","R",IF(I7="Carousel","C","I"))&"_"&J7&"_"&IF(K7="AI tự động","AI","HU")&"_"&RIGHT(A7,3) -> P2_EXP1_C_A_AI_001 | U7: =IF(O7>0,P7/O7,"") | V7: =IF(P7>0,Q7/P7,"") | W7: =IF(R7<>"",R7,Q7*'Cài đặt'!$B$12) -> 0 | X7: =IF(O7>0,W7/O7*1000,"") | Y7: =IF(T7<>"",T7,INDEX('Cài đặt'!$B$20:$C$22,MATCH(I7,'Cài đặt'!$A$20:$A$22,0),IF(K7="AI tự động",1,2))) -> 4
A8: E1-P2-002 | B8: EXP1 | C8: P2 | D8: =INDEX('Page và Ngách'!$B$5:$B$10,MATCH(C8,'Page và Ngách'!$A$5:$A$10,0)) -> Secret billionaire / CEO | E8: 1 | F8: ='Cài đặt'!$B$37+E8-1 -> 46335 | G8: S2 | H8: =IF(G8="S1",'Cài đặt'!$B$7,'Cài đặt'!$B$8) -> 20:00 | I8: Reel | J8: A | K8: AI tự động | L8: =C8&"_"&B8&"_"&IF(I8="Reel","R",IF(I8="Carousel","C","I"))&"_"&J8&"_"&IF(K8="AI tự động","AI","HU")&"_"&RIGHT(A8,3) -> P2_EXP1_R_A_AI_002 | U8: =IF(O8>0,P8/O8,"") | V8: =IF(P8>0,Q8/P8,"") | W8: =IF(R8<>"",R8,Q8*'Cài đặt'!$B$12) -> 0 | X8: =IF(O8>0,W8/O8*1000,"") | Y8: =IF(T8<>"",T8,INDEX('Cài đặt'!$B$20:$C$22,MATCH(I8,'Cài đặt'!$A$20:$A$22,0),IF(K8="AI tự động",1,2))) -> 8
A9: E1-P3-001 | B9: EXP1 | C9: P3 | D9: =INDEX('Page và Ngách'!$B$5:$B$10,MATCH(C9,'Page và Ngách'!$A$5:$A$10,0)) -> Contract marriage / Fake relationship | E9: 1 | F9: ='Cài đặt'!$B$37+E9-1 -> 46335 | G9: S1 | H9: =IF(G9="S1",'Cài đặt'!$B$7,'Cài đặt'!$B$8) -> 12:00 | I9: Reel | J9: A | K9: AI tự động | L9: =C9&"_"&B9&"_"&IF(I9="Reel","R",IF(I9="Carousel","C","I"))&"_"&J9&"_"&IF(K9="AI tự động","AI","HU")&"_"&RIGHT(A9,3) -> P3_EXP1_R_A_AI_001 | U9: =IF(O9>0,P9/O9,"") | V9: =IF(P9>0,Q9/P9,"") | W9: =IF(R9<>"",R9,Q9*'Cài đặt'!$B$12) -> 0 | X9: =IF(O9>0,W9/O9*1000,"") | Y9: =IF(T9<>"",T9,INDEX('Cài đặt'!$B$20:$C$22,MATCH(I9,'Cài đặt'!$A$20:$A$22,0),IF(K9="AI tự động",1,2))) -> 8
A10: E1-P3-002 | B10: EXP1 | C10: P3 | D10: =INDEX('Page và Ngách'!$B$5:$B$10,MATCH(C10,'Page và Ngách'!$A$5:$A$10,0)) -> Contract marriage / Fake relationship | E10: 1 | F10: ='Cài đặt'!$B$37+E10-1 -> 46335 | G10: S2 | H10: =IF(G10="S1",'Cài đặt'!$B$7,'Cài đặt'!$B$8) -> 20:00 | I10: Ảnh chữ | J10: A | K10: AI tự động | L10: =C10&"_"&B10&"_"&IF(I10="Reel","R",IF(I10="Carousel","C","I"))&"_"&J10&"_"&IF(K10="AI tự động","AI","HU")&"_"&RIGHT(A10,3) -> P3_EXP1_I_A_AI_002 | U10: =IF(O10>0,P10/O10,"") | V10: =IF(P10>0,Q10/P10,"") | W10: =IF(R10<>"",R10,Q10*'Cài đặt'!$B$12) -> 0 | X10: =IF(O10>0,W10/O10*1000,"") | Y10: =IF(T10<>"",T10,INDEX('Cài đặt'!$B$20:$C$22,MATCH(I10,'Cài đặt'!$A$20:$A$22,0),IF(K10="AI tự động",1,2))) -> 2
A11: E1-P4-001 | B11: EXP1 | C11: P4 | D11: =INDEX('Page và Ngách'!$B$5:$B$10,MATCH(C11,'Page và Ngách'!$A$5:$A$10,0)) -> Revenge / Betrayal ("you'll regret it") | E11: 1 | F11: ='Cài đặt'!$B$37+E11-1 -> 46335 | G11: S1 | H11: =IF(G11="S1",'Cài đặt'!$B$7,'Cài đặt'!$B$8) -> 12:00 | I11: Ảnh chữ | J11: A | K11: AI tự động | L11: =C11&"_"&B11&"_"&IF(I11="Reel","R",IF(I11="Carousel","C","I"))&"_"&J11&"_"&IF(K11="AI tự động","AI","HU")&"_"&RIGHT(A11,3) -> P4_EXP1_I_A_AI_001 | U11: =IF(O11>0,P11/O11,"") | V11: =IF(P11>0,Q11/P11,"") | W11: =IF(R11<>"",R11,Q11*'Cài đặt'!$B$12) -> 0 | X11: =IF(O11>0,W11/O11*1000,"") | Y11: =IF(T11<>"",T11,INDEX('Cài đặt'!$B$20:$C$22,MATCH(I11,'Cài đặt'!$A$20:$A$22,0),IF(K11="AI tự động",1,2))) -> 2
A12: E1-P4-002 | B12: EXP1 | C12: P4 | D12: =INDEX('Page và Ngách'!$B$5:$B$10,MATCH(C12,'Page và Ngách'!$A$5:$A$10,0)) -> Revenge / Betrayal ("you'll regret it") | E12: 1 | F12: ='Cài đặt'!$B$37+E12-1 -> 46335 | G12: S2 | H12: =IF(G12="S1",'Cài đặt'!$B$7,'Cài đặt'!$B$8) -> 20:00 | I12: Carousel | J12: A | K12: AI tự động | L12: =C12&"_"&B12&"_"&IF(I12="Reel","R",IF(I12="Carousel","C","I"))&"_"&J12&"_"&IF(K12="AI tự động","AI","HU")&"_"&RIGHT(A12,3) -> P4_EXP1_C_A_AI_002 | U12: =IF(O12>0,P12/O12,"") | V12: =IF(P12>0,Q12/P12,"") | W12: =IF(R12<>"",R12,Q12*'Cài đặt'!$B$12) -> 0 | X12: =IF(O12>0,W12/O12*1000,"") | Y12: =IF(T12<>"",T12,INDEX('Cài đặt'!$B$20:$C$22,MATCH(I12,'Cài đặt'!$A$20:$A$22,0),IF(K12="AI tự động",1,2))) -> 4
A13: E1-P5-001 | B13: EXP1 | C13: P5 | D13: =INDEX('Page và Ngách'!$B$5:$B$10,MATCH(C13,'Page và Ngách'!$A$5:$A$10,0)) -> Mafia / Dark romance (teaser PG-13) | E13: 1 | F13: ='Cài đặt'!$B$37+E13-1 -> 46335 | G13: S1 | H13: =IF(G13="S1",'Cài đặt'!$B$7,'Cài đặt'!$B$8) -> 12:00 | I13: Carousel | J13: A | K13: AI tự động | L13: =C13&"_"&B13&"_"&IF(I13="Reel","R",IF(I13="Carousel","C","I"))&"_"&J13&"_"&IF(K13="AI tự động","AI","HU")&"_"&RIGHT(A13,3) -> P5_EXP1_C_A_AI_001 | U13: =IF(O13>0,P13/O13,"") | V13: =IF(P13>0,Q13/P13,"") | W13: =IF(R13<>"",R13,Q13*'Cài đặt'!$B$12) -> 0 | X13: =IF(O13>0,W13/O13*1000,"") | Y13: =IF(T13<>"",T13,INDEX('Cài đặt'!$B$20:$C$22,MATCH(I13,'Cài đặt'!$A$20:$A$22,0),IF(K13="AI tự động",1,2))) -> 4
A14: E1-P5-002 | B14: EXP1 | C14: P5 | D14: =INDEX('Page và Ngách'!$B$5:$B$10,MATCH(C14,'Page và Ngách'!$A$5:$A$10,0)) -> Mafia / Dark romance (teaser PG-13) | E14: 1 | F14: ='Cài đặt'!$B$37+E14-1 -> 46335 | G14: S2 | H14: =IF(G14="S1",'Cài đặt'!$B$7,'Cài đặt'!$B$8) -> 20:00 | I14: Reel | J14: A | K14: AI tự động | L14: =C14&"_"&B14&"_"&IF(I14="Reel","R",IF(I14="Carousel","C","I"))&"_"&J14&"_"&IF(K14="AI tự động","AI","HU")&"_"&RIGHT(A14,3) -> P5_EXP1_R_A_AI_002 | U14: =IF(O14>0,P14/O14,"") | V14: =IF(P14>0,Q14/P14,"") | W14: =IF(R14<>"",R14,Q14*'Cài đặt'!$B$12) -> 0 | X14: =IF(O14>0,W14/O14*1000,"") | Y14: =IF(T14<>"",T14,INDEX('Cài đặt'!$B$20:$C$22,MATCH(I14,'Cài đặt'!$A$20:$A$22,0),IF(K14="AI tự động",1,2))) -> 8
A15: E1-P6-001 | B15: EXP1 | C15: P6 | D15: =INDEX('Page và Ngách'!$B$5:$B$10,MATCH(C15,'Page và Ngách'!$A$5:$A$10,0)) -> Second chance / Secret baby | E15: 1 | F15: ='Cài đặt'!$B$37+E15-1 -> 46335 | G15: S1 | H15: =IF(G15="S1",'Cài đặt'!$B$7,'Cài đặt'!$B$8) -> 12:00 | I15: Reel | J15: A | K15: AI tự động | L15: =C15&"_"&B15&"_"&IF(I15="Reel","R",IF(I15="Carousel","C","I"))&"_"&J15&"_"&IF(K15="AI tự động","AI","HU")&"_"&RIGHT(A15,3) -> P6_EXP1_R_A_AI_001 | U15: =IF(O15>0,P15/O15,"") | V15: =IF(P15>0,Q15/P15,"") | W15: =IF(R15<>"",R15,Q15*'Cài đặt'!$B$12) -> 0 | X15: =IF(O15>0,W15/O15*1000,"") | Y15: =IF(T15<>"",T15,INDEX('Cài đặt'!$B$20:$C$22,MATCH(I15,'Cài đặt'!$A$20:$A$22,0),IF(K15="AI tự động",1,2))) -> 8
A16: E1-P6-002 | B16: EXP1 | C16: P6 | D16: =INDEX('Page và Ngách'!$B$5:$B$10,MATCH(C16,'Page và Ngách'!$A$5:$A$10,0)) -> Second chance / Secret baby | E16: 1 | F16: ='Cài đặt'!$B$37+E16-1 -> 46335 | G16: S2 | H16: =IF(G16="S1",'Cài đặt'!$B$7,'Cài đặt'!$B$8) -> 20:00 | I16: Ảnh chữ | J16: A | K16: AI tự động | L16: =C16&"_"&B16&"_"&IF(I16="Reel","R",IF(I16="Carousel","C","I"))&"_"&J16&"_"&IF(K16="AI tự động","AI","HU")&"_"&RIGHT(A16,3) -> P6_EXP1_I_A_AI_002 | U16: =IF(O16>0,P16/O16,"") | V16: =IF(P16>0,Q16/P16,"") | W16: =IF(R16<>"",R16,Q16*'Cài đặt'!$B$12) -> 0 | X16: =IF(O16>0,W16/O16*1000,"") | Y16: =IF(T16<>"",T16,INDEX('Cài đặt'!$B$20:$C$22,MATCH(I16,'Cài đặt'!$A$20:$A$22,0),IF(K16="AI tự động",1,2))) -> 2
... A256: E1-P6-042 | B256: EXP1 | C256: P6 | D256: =INDEX('Page và Ngách'!$B$5:$B$10,MATCH(C256,'Page và Ngách'!$A$5:$A$10,0)) -> Second chance / Secret baby | E256: 21 | F256: ='Cài đặt'!$B$37+E256-1 -> 46355 | G256: S2 | H256: =IF(G256="S1",'Cài đặt'!$B$7,'Cài đặt'!$B$8) -> 20:00 | I256: Carousel | J256: A | K256: AI tự động | L256: =C256&"_"&B256&"_"&IF(I256="Reel","R",IF(I256="Carousel","C","I"))&"_"&J256&"_"&IF(K256="AI tự động","AI","HU")&"_"&RIGHT(A256,3) -> P6_EXP1_C_A_AI_042 | U256: =IF(O256>0,P256/O256,"") | V256: =IF(P256>0,Q256/P256,"") | W256: =IF(R256<>"",R256,Q256*'Cài đặt'!$B$12) -> 0 | X256: =IF(O256>0,W256/O256*1000,"") | Y256: =IF(T256<>"",T256,INDEX('Cài đặt'!$B$20:$C$22,MATCH(I256,'Cài đặt'!$A$20:$A$22,0),IF(K256="AI tự động",1,2))) -> 4
A257: E2-P1-001 | B257: EXP2 | C257: P1 | D257: =INDEX('Page và Ngách'!$B$5:$B$10,MATCH(C257,'Page và Ngách'!$A$5:$A$10,0)) -> Werewolf / Rejected mate | E257: 1 | F257: ='Cài đặt'!$B$38+E257-1 -> 46356 | G257: S1 | H257: =IF(G257="S1",'Cài đặt'!$B$7,'Cài đặt'!$B$8) -> 12:00 | I257: ='Cài đặt'!$B$32 -> Carousel | J257: B | K257: AI tự động | L257: =C257&"_"&B257&"_"&IF(I257="Reel","R",IF(I257="Carousel","C","I"))&"_"&J257&"_"&IF(K257="AI tự động","AI","HU")&"_"&RIGHT(A257,3) -> P1_EXP2_C_B_AI_001 | U257: =IF(O257>0,P257/O257,"") | V257: =IF(P257>0,Q257/P257,"") | W257: =IF(R257<>"",R257,Q257*'Cài đặt'!$B$12) -> 0 | X257: =IF(O257>0,W257/O257*1000,"") | Y257: =IF(T257<>"",T257,INDEX('Cài đặt'!$B$20:$C$22,MATCH(I257,'Cài đặt'!$A$20:$A$22,0),IF(K257="AI tự động",1,2))) -> 4
A258: E2-P1-002 | B258: EXP2 | C258: P1 | D258: =INDEX('Page và Ngách'!$B$5:$B$10,MATCH(C258,'Page và Ngách'!$A$5:$A$10,0)) -> Werewolf / Rejected mate | E258: 1 | F258: ='Cài đặt'!$B$38+E258-1 -> 46356 | G258: S2 | H258: =IF(G258="S1",'Cài đặt'!$B$7,'Cài đặt'!$B$8) -> 20:00 | I258: ='Cài đặt'!$B$32 -> Carousel | J258: C | K258: AI tự động | L258: =C258&"_"&B258&"_"&IF(I258="Reel","R",IF(I258="Carousel","C","I"))&"_"&J258&"_"&IF(K258="AI tự động","AI","HU")&"_"&RIGHT(A258,3) -> P1_EXP2_C_C_AI_002 | U258: =IF(O258>0,P258/O258,"") | V258: =IF(P258>0,Q258/P258,"") | W258: =IF(R258<>"",R258,Q258*'Cài đặt'!$B$12) -> 0 | X258: =IF(O258>0,W258/O258*1000,"") | Y258: =IF(T258<>"",T258,INDEX('Cài đặt'!$B$20:$C$22,MATCH(I258,'Cài đặt'!$A$20:$A$22,0),IF(K258="AI tự động",1,2))) -> 4
A259: E2-P2-001 | B259: EXP2 | C259: P2 | D259: =INDEX('Page và Ngách'!$B$5:$B$10,MATCH(C259,'Page và Ngách'!$A$5:$A$10,0)) -> Secret billionaire / CEO | E259: 1 | F259: ='Cài đặt'!$B$38+E259-1 -> 46356 | G259: S1 | H259: =IF(G259="S1",'Cài đặt'!$B$7,'Cài đặt'!$B$8) -> 12:00 | I259: ='Cài đặt'!$B$32 -> Carousel | J259: C | K259: AI tự động | L259: =C259&"_"&B259&"_"&IF(I259="Reel","R",IF(I259="Carousel","C","I"))&"_"&J259&"_"&IF(K259="AI tự động","AI","HU")&"_"&RIGHT(A259,3) -> P2_EXP2_C_C_AI_001 | U259: =IF(O259>0,P259/O259,"") | V259: =IF(P259>0,Q259/P259,"") | W259: =IF(R259<>"",R259,Q259*'Cài đặt'!$B$12) -> 0 | X259: =IF(O259>0,W259/O259*1000,"") | Y259: =IF(T259<>"",T259,INDEX('Cài đặt'!$B$20:$C$22,MATCH(I259,'Cài đặt'!$A$20:$A$22,0),IF(K259="AI tự động",1,2))) -> 4
A260: E2-P2-002 | B260: EXP2 | C260: P2 | D260: =INDEX('Page và Ngách'!$B$5:$B$10,MATCH(C260,'Page và Ngách'!$A$5:$A$10,0)) -> Secret billionaire / CEO | E260: 1 | F260: ='Cài đặt'!$B$38+E260-1 -> 46356 | G260: S2 | H260: =IF(G260="S1",'Cài đặt'!$B$7,'Cài đặt'!$B$8) -> 20:00 | I260: ='Cài đặt'!$B$32 -> Carousel | J260: A | K260: AI tự động | L260: =C260&"_"&B260&"_"&IF(I260="Reel","R",IF(I260="Carousel","C","I"))&"_"&J260&"_"&IF(K260="AI tự động","AI","HU")&"_"&RIGHT(A260,3) -> P2_EXP2_C_A_AI_002 | U260: =IF(O260>0,P260/O260,"") | V260: =IF(P260>0,Q260/P260,"") | W260: =IF(R260<>"",R260,Q260*'Cài đặt'!$B$12) -> 0 | X260: =IF(O260>0,W260/O260*1000,"") | Y260: =IF(T260<>"",T260,INDEX('Cài đặt'!$B$20:$C$22,MATCH(I260,'Cài đặt'!$A$20:$A$22,0),IF(K260="AI tự động",1,2))) -> 4
A261: E2-P3-001 | B261: EXP2 | C261: P3 | D261: =INDEX('Page và Ngách'!$B$5:$B$10,MATCH(C261,'Page và Ngách'!$A$5:$A$10,0)) -> Contract marriage / Fake relationship | E261: 1 | F261: ='Cài đặt'!$B$38+E261-1 -> 46356 | G261: S1 | H261: =IF(G261="S1",'Cài đặt'!$B$7,'Cài đặt'!$B$8) -> 12:00 | I261: ='Cài đặt'!$B$32 -> Carousel | J261: A | K261: AI tự động | L261: =C261&"_"&B261&"_"&IF(I261="Reel","R",IF(I261="Carousel","C","I"))&"_"&J261&"_"&IF(K261="AI tự động","AI","HU")&"_"&RIGHT(A261,3) -> P3_EXP2_C_A_AI_001 | U261: =IF(O261>0,P261/O261,"") | V261: =IF(P261>0,Q261/P261,"") | W261: =IF(R261<>"",R261,Q261*'Cài đặt'!$B$12) -> 0 | X261: =IF(O261>0,W261/O261*1000,"") | Y261: =IF(T261<>"",T261,INDEX('Cài đặt'!$B$20:$C$22,MATCH(I261,'Cài đặt'!$A$20:$A$22,0),IF(K261="AI tự động",1,2))) -> 4
A262: E2-P3-002 | B262: EXP2 | C262: P3 | D262: =INDEX('Page và Ngách'!$B$5:$B$10,MATCH(C262,'Page và Ngách'!$A$5:$A$10,0)) -> Contract marriage / Fake relationship | E262: 1 | F262: ='Cài đặt'!$B$38+E262-1 -> 46356 | G262: S2 | H262: =IF(G262="S1",'Cài đặt'!$B$7,'Cài đặt'!$B$8) -> 20:00 | I262: ='Cài đặt'!$B$32 -> Carousel | J262: B | K262: AI tự động | L262: =C262&"_"&B262&"_"&IF(I262="Reel","R",IF(I262="Carousel","C","I"))&"_"&J262&"_"&IF(K262="AI tự động","AI","HU")&"_"&RIGHT(A262,3) -> P3_EXP2_C_B_AI_002 | U262: =IF(O262>0,P262/O262,"") | V262: =IF(P262>0,Q262/P262,"") | W262: =IF(R262<>"",R262,Q262*'Cài đặt'!$B$12) -> 0 | X262: =IF(O262>0,W262/O262*1000,"") | Y262: =IF(T262<>"",T262,INDEX('Cài đặt'!$B$20:$C$22,MATCH(I262,'Cài đặt'!$A$20:$A$22,0),IF(K262="AI tự động",1,2))) -> 4
A263: E2-P4-001 | B263: EXP2 | C263: P4 | D263: =INDEX('Page và Ngách'!$B$5:$B$10,MATCH(C263,'Page và Ngách'!$A$5:$A$10,0)) -> Revenge / Betrayal ("you'll regret it") | E263: 1 | F263: ='Cài đặt'!$B$38+E263-1 -> 46356 | G263: S1 | H263: =IF(G263="S1",'Cài đặt'!$B$7,'Cài đặt'!$B$8) -> 12:00 | I263: ='Cài đặt'!$B$32 -> Carousel | J263: B | K263: AI tự động | L263: =C263&"_"&B263&"_"&IF(I263="Reel","R",IF(I263="Carousel","C","I"))&"_"&J263&"_"&IF(K263="AI tự động","AI","HU")&"_"&RIGHT(A263,3) -> P4_EXP2_C_B_AI_001 | U263: =IF(O263>0,P263/O263,"") | V263: =IF(P263>0,Q263/P263,"") | W263: =IF(R263<>"",R263,Q263*'Cài đặt'!$B$12) -> 0 | X263: =IF(O263>0,W263/O263*1000,"") | Y263: =IF(T263<>"",T263,INDEX('Cài đặt'!$B$20:$C$22,MATCH(I263,'Cài đặt'!$A$20:$A$22,0),IF(K263="AI tự động",1,2))) -> 4
A264: E2-P4-002 | B264: EXP2 | C264: P4 | D264: =INDEX('Page và Ngách'!$B$5:$B$10,MATCH(C264,'Page và Ngách'!$A$5:$A$10,0)) -> Revenge / Betrayal ("you'll regret it") | E264: 1 | F264: ='Cài đặt'!$B$38+E264-1 -> 46356 | G264: S2 | H264: =IF(G264="S1",'Cài đặt'!$B$7,'Cài đặt'!$B$8) -> 20:00 | I264: ='Cài đặt'!$B$32 -> Carousel | J264: C | K264: AI tự động | L264: =C264&"_"&B264&"_"&IF(I264="Reel","R",IF(I264="Carousel","C","I"))&"_"&J264&"_"&IF(K264="AI tự động","AI","HU")&"_"&RIGHT(A264,3) -> P4_EXP2_C_C_AI_002 | U264: =IF(O264>0,P264/O264,"") | V264: =IF(P264>0,Q264/P264,"") | W264: =IF(R264<>"",R264,Q264*'Cài đặt'!$B$12) -> 0 | X264: =IF(O264>0,W264/O264*1000,"") | Y264: =IF(T264<>"",T264,INDEX('Cài đặt'!$B$20:$C$22,MATCH(I264,'Cài đặt'!$A$20:$A$22,0),IF(K264="AI tự động",1,2))) -> 4
A265: E2-P5-001 | B265: EXP2 | C265: P5 | D265: =INDEX('Page và Ngách'!$B$5:$B$10,MATCH(C265,'Page và Ngách'!$A$5:$A$10,0)) -> Mafia / Dark romance (teaser PG-13) | E265: 1 | F265: ='Cài đặt'!$B$38+E265-1 -> 46356 | G265: S1 | H265: =IF(G265="S1",'Cài đặt'!$B$7,'Cài đặt'!$B$8) -> 12:00 | I265: ='Cài đặt'!$B$32 -> Carousel | J265: C | K265: AI tự động | L265: =C265&"_"&B265&"_"&IF(I265="Reel","R",IF(I265="Carousel","C","I"))&"_"&J265&"_"&IF(K265="AI tự động","AI","HU")&"_"&RIGHT(A265,3) -> P5_EXP2_C_C_AI_001 | U265: =IF(O265>0,P265/O265,"") | V265: =IF(P265>0,Q265/P265,"") | W265: =IF(R265<>"",R265,Q265*'Cài đặt'!$B$12) -> 0 | X265: =IF(O265>0,W265/O265*1000,"") | Y265: =IF(T265<>"",T265,INDEX('Cài đặt'!$B$20:$C$22,MATCH(I265,'Cài đặt'!$A$20:$A$22,0),IF(K265="AI tự động",1,2))) -> 4
A266: E2-P5-002 | B266: EXP2 | C266: P5 | D266: =INDEX('Page và Ngách'!$B$5:$B$10,MATCH(C266,'Page và Ngách'!$A$5:$A$10,0)) -> Mafia / Dark romance (teaser PG-13) | E266: 1 | F266: ='Cài đặt'!$B$38+E266-1 -> 46356 | G266: S2 | H266: =IF(G266="S1",'Cài đặt'!$B$7,'Cài đặt'!$B$8) -> 20:00 | I266: ='Cài đặt'!$B$32 -> Carousel | J266: A | K266: AI tự động | L266: =C266&"_"&B266&"_"&IF(I266="Reel","R",IF(I266="Carousel","C","I"))&"_"&J266&"_"&IF(K266="AI tự động","AI","HU")&"_"&RIGHT(A266,3) -> P5_EXP2_C_A_AI_002 | U266: =IF(O266>0,P266/O266,"") | V266: =IF(P266>0,Q266/P266,"") | W266: =IF(R266<>"",R266,Q266*'Cài đặt'!$B$12) -> 0 | X266: =IF(O266>0,W266/O266*1000,"") | Y266: =IF(T266<>"",T266,INDEX('Cài đặt'!$B$20:$C$22,MATCH(I266,'Cài đặt'!$A$20:$A$22,0),IF(K266="AI tự động",1,2))) -> 4
A267: E2-P6-001 | B267: EXP2 | C267: P6 | D267: =INDEX('Page và Ngách'!$B$5:$B$10,MATCH(C267,'Page và Ngách'!$A$5:$A$10,0)) -> Second chance / Secret baby | E267: 1 | F267: ='Cài đặt'!$B$38+E267-1 -> 46356 | G267: S1 | H267: =IF(G267="S1",'Cài đặt'!$B$7,'Cài đặt'!$B$8) -> 12:00 | I267: ='Cài đặt'!$B$32 -> Carousel | J267: A | K267: AI tự động | L267: =C267&"_"&B267&"_"&IF(I267="Reel","R",IF(I267="Carousel","C","I"))&"_"&J267&"_"&IF(K267="AI tự động","AI","HU")&"_"&RIGHT(A267,3) -> P6_EXP2_C_A_AI_001 | U267: =IF(O267>0,P267/O267,"") | V267: =IF(P267>0,Q267/P267,"") | W267: =IF(R267<>"",R267,Q267*'Cài đặt'!$B$12) -> 0 | X267: =IF(O267>0,W267/O267*1000,"") | Y267: =IF(T267<>"",T267,INDEX('Cài đặt'!$B$20:$C$22,MATCH(I267,'Cài đặt'!$A$20:$A$22,0),IF(K267="AI tự động",1,2))) -> 4
A268: E2-P6-002 | B268: EXP2 | C268: P6 | D268: =INDEX('Page và Ngách'!$B$5:$B$10,MATCH(C268,'Page và Ngách'!$A$5:$A$10,0)) -> Second chance / Secret baby | E268: 1 | F268: ='Cài đặt'!$B$38+E268-1 -> 46356 | G268: S2 | H268: =IF(G268="S1",'Cài đặt'!$B$7,'Cài đặt'!$B$8) -> 20:00 | I268: ='Cài đặt'!$B$32 -> Carousel | J268: B | K268: AI tự động | L268: =C268&"_"&B268&"_"&IF(I268="Reel","R",IF(I268="Carousel","C","I"))&"_"&J268&"_"&IF(K268="AI tự động","AI","HU")&"_"&RIGHT(A268,3) -> P6_EXP2_C_B_AI_002 | U268: =IF(O268>0,P268/O268,"") | V268: =IF(P268>0,Q268/P268,"") | W268: =IF(R268<>"",R268,Q268*'Cài đặt'!$B$12) -> 0 | X268: =IF(O268>0,W268/O268*1000,"") | Y268: =IF(T268<>"",T268,INDEX('Cài đặt'!$B$20:$C$22,MATCH(I268,'Cài đặt'!$A$20:$A$22,0),IF(K268="AI tự động",1,2))) -> 4
... A508: E2-P6-042 | B508: EXP2 | C508: P6 | D508: =INDEX('Page và Ngách'!$B$5:$B$10,MATCH(C508,'Page và Ngách'!$A$5:$A$10,0)) -> Second chance / Secret baby | E508: 21 | F508: ='Cài đặt'!$B$38+E508-1 -> 46376 | G508: S2 | H508: =IF(G508="S1",'Cài đặt'!$B$7,'Cài đặt'!$B$8) -> 20:00 | I508: ='Cài đặt'!$B$32 -> Carousel | J508: C | K508: AI tự động | L508: =C508&"_"&B508&"_"&IF(I508="Reel","R",IF(I508="Carousel","C","I"))&"_"&J508&"_"&IF(K508="AI tự động","AI","HU")&"_"&RIGHT(A508,3) -> P6_EXP2_C_C_AI_042 | U508: =IF(O508>0,P508/O508,"") | V508: =IF(P508>0,Q508/P508,"") | W508: =IF(R508<>"",R508,Q508*'Cài đặt'!$B$12) -> 0 | X508: =IF(O508>0,W508/O508*1000,"") | Y508: =IF(T508<>"",T508,INDEX('Cài đặt'!$B$20:$C$22,MATCH(I508,'Cài đặt'!$A$20:$A$22,0),IF(K508="AI tự động",1,2))) -> 4
A509: E3-P1-001 | B509: EXP3 | C509: P1 | D509: =INDEX('Page và Ngách'!$B$5:$B$10,MATCH(C509,'Page và Ngách'!$A$5:$A$10,0)) -> Werewolf / Rejected mate | E509: 1 | F509: ='Cài đặt'!$B$39+E509-1 -> 46377 | G509: S1 | H509: =IF(G509="S1",'Cài đặt'!$B$7,'Cài đặt'!$B$8) -> 12:00 | I509: ='Cài đặt'!$B$32 -> Carousel | J509: ='Cài đặt'!$B$33 -> A | K509: AI tự động | L509: =C509&"_"&B509&"_"&IF(I509="Reel","R",IF(I509="Carousel","C","I"))&"_"&J509&"_"&IF(K509="AI tự động","AI","HU")&"_"&RIGHT(A509,3) -> P1_EXP3_C_A_AI_001 | U509: =IF(O509>0,P509/O509,"") | V509: =IF(P509>0,Q509/P509,"") | W509: =IF(R509<>"",R509,Q509*'Cài đặt'!$B$12) -> 0 | X509: =IF(O509>0,W509/O509*1000,"") | Y509: =IF(T509<>"",T509,INDEX('Cài đặt'!$B$20:$C$22,MATCH(I509,'Cài đặt'!$A$20:$A$22,0),IF(K509="AI tự động",1,2))) -> 4
A510: E3-P1-002 | B510: EXP3 | C510: P1 | D510: =INDEX('Page và Ngách'!$B$5:$B$10,MATCH(C510,'Page và Ngách'!$A$5:$A$10,0)) -> Werewolf / Rejected mate | E510: 1 | F510: ='Cài đặt'!$B$39+E510-1 -> 46377 | G510: S2 | H510: =IF(G510="S1",'Cài đặt'!$B$7,'Cài đặt'!$B$8) -> 20:00 | I510: ='Cài đặt'!$B$32 -> Carousel | J510: ='Cài đặt'!$B$33 -> A | K510: AI tự động | L510: =C510&"_"&B510&"_"&IF(I510="Reel","R",IF(I510="Carousel","C","I"))&"_"&J510&"_"&IF(K510="AI tự động","AI","HU")&"_"&RIGHT(A510,3) -> P1_EXP3_C_A_AI_002 | U510: =IF(O510>0,P510/O510,"") | V510: =IF(P510>0,Q510/P510,"") | W510: =IF(R510<>"",R510,Q510*'Cài đặt'!$B$12) -> 0 | X510: =IF(O510>0,W510/O510*1000,"") | Y510: =IF(T510<>"",T510,INDEX('Cài đặt'!$B$20:$C$22,MATCH(I510,'Cài đặt'!$A$20:$A$22,0),IF(K510="AI tự động",1,2))) -> 4
A511: E3-P2-001 | B511: EXP3 | C511: P2 | D511: =INDEX('Page và Ngách'!$B$5:$B$10,MATCH(C511,'Page và Ngách'!$A$5:$A$10,0)) -> Secret billionaire / CEO | E511: 1 | F511: ='Cài đặt'!$B$39+E511-1 -> 46377 | G511: S1 | H511: =IF(G511="S1",'Cài đặt'!$B$7,'Cài đặt'!$B$8) -> 12:00 | I511: ='Cài đặt'!$B$32 -> Carousel | J511: ='Cài đặt'!$B$33 -> A | K511: Human nghiên cứu | L511: =C511&"_"&B511&"_"&IF(I511="Reel","R",IF(I511="Carousel","C","I"))&"_"&J511&"_"&IF(K511="AI tự động","AI","HU")&"_"&RIGHT(A511,3) -> P2_EXP3_C_A_HU_001 | U511: =IF(O511>0,P511/O511,"") | V511: =IF(P511>0,Q511/P511,"") | W511: =IF(R511<>"",R511,Q511*'Cài đặt'!$B$12) -> 0 | X511: =IF(O511>0,W511/O511*1000,"") | Y511: =IF(T511<>"",T511,INDEX('Cài đặt'!$B$20:$C$22,MATCH(I511,'Cài đặt'!$A$20:$A$22,0),IF(K511="AI tự động",1,2))) -> 25
A512: E3-P2-002 | B512: EXP3 | C512: P2 | D512: =INDEX('Page và Ngách'!$B$5:$B$10,MATCH(C512,'Page và Ngách'!$A$5:$A$10,0)) -> Secret billionaire / CEO | E512: 1 | F512: ='Cài đặt'!$B$39+E512-1 -> 46377 | G512: S2 | H512: =IF(G512="S1",'Cài đặt'!$B$7,'Cài đặt'!$B$8) -> 20:00 | I512: ='Cài đặt'!$B$32 -> Carousel | J512: ='Cài đặt'!$B$33 -> A | K512: AI tự động | L512: =C512&"_"&B512&"_"&IF(I512="Reel","R",IF(I512="Carousel","C","I"))&"_"&J512&"_"&IF(K512="AI tự động","AI","HU")&"_"&RIGHT(A512,3) -> P2_EXP3_C_A_AI_002 | U512: =IF(O512>0,P512/O512,"") | V512: =IF(P512>0,Q512/P512,"") | W512: =IF(R512<>"",R512,Q512*'Cài đặt'!$B$12) -> 0 | X512: =IF(O512>0,W512/O512*1000,"") | Y512: =IF(T512<>"",T512,INDEX('Cài đặt'!$B$20:$C$22,MATCH(I512,'Cài đặt'!$A$20:$A$22,0),IF(K512="AI tự động",1,2))) -> 4
A513: E3-P3-001 | B513: EXP3 | C513: P3 | D513: =INDEX('Page và Ngách'!$B$5:$B$10,MATCH(C513,'Page và Ngách'!$A$5:$A$10,0)) -> Contract marriage / Fake relationship | E513: 1 | F513: ='Cài đặt'!$B$39+E513-1 -> 46377 | G513: S1 | H513: =IF(G513="S1",'Cài đặt'!$B$7,'Cài đặt'!$B$8) -> 12:00 | I513: ='Cài đặt'!$B$32 -> Carousel | J513: ='Cài đặt'!$B$33 -> A | K513: AI tự động | L513: =C513&"_"&B513&"_"&IF(I513="Reel","R",IF(I513="Carousel","C","I"))&"_"&J513&"_"&IF(K513="AI tự động","AI","HU")&"_"&RIGHT(A513,3) -> P3_EXP3_C_A_AI_001 | U513: =IF(O513>0,P513/O513,"") | V513: =IF(P513>0,Q513/P513,"") | W513: =IF(R513<>"",R513,Q513*'Cài đặt'!$B$12) -> 0 | X513: =IF(O513>0,W513/O513*1000,"") | Y513: =IF(T513<>"",T513,INDEX('Cài đặt'!$B$20:$C$22,MATCH(I513,'Cài đặt'!$A$20:$A$22,0),IF(K513="AI tự động",1,2))) -> 4
A514: E3-P3-002 | B514: EXP3 | C514: P3 | D514: =INDEX('Page và Ngách'!$B$5:$B$10,MATCH(C514,'Page và Ngách'!$A$5:$A$10,0)) -> Contract marriage / Fake relationship | E514: 1 | F514: ='Cài đặt'!$B$39+E514-1 -> 46377 | G514: S2 | H514: =IF(G514="S1",'Cài đặt'!$B$7,'Cài đặt'!$B$8) -> 20:00 | I514: ='Cài đặt'!$B$32 -> Carousel | J514: ='Cài đặt'!$B$33 -> A | K514: AI tự động | L514: =C514&"_"&B514&"_"&IF(I514="Reel","R",IF(I514="Carousel","C","I"))&"_"&J514&"_"&IF(K514="AI tự động","AI","HU")&"_"&RIGHT(A514,3) -> P3_EXP3_C_A_AI_002 | U514: =IF(O514>0,P514/O514,"") | V514: =IF(P514>0,Q514/P514,"") | W514: =IF(R514<>"",R514,Q514*'Cài đặt'!$B$12) -> 0 | X514: =IF(O514>0,W514/O514*1000,"") | Y514: =IF(T514<>"",T514,INDEX('Cài đặt'!$B$20:$C$22,MATCH(I514,'Cài đặt'!$A$20:$A$22,0),IF(K514="AI tự động",1,2))) -> 4
A515: E3-P4-001 | B515: EXP3 | C515: P4 | D515: =INDEX('Page và Ngách'!$B$5:$B$10,MATCH(C515,'Page và Ngách'!$A$5:$A$10,0)) -> Revenge / Betrayal ("you'll regret it") | E515: 1 | F515: ='Cài đặt'!$B$39+E515-1 -> 46377 | G515: S1 | H515: =IF(G515="S1",'Cài đặt'!$B$7,'Cài đặt'!$B$8) -> 12:00 | I515: ='Cài đặt'!$B$32 -> Carousel | J515: ='Cài đặt'!$B$33 -> A | K515: AI tự động | L515: =C515&"_"&B515&"_"&IF(I515="Reel","R",IF(I515="Carousel","C","I"))&"_"&J515&"_"&IF(K515="AI tự động","AI","HU")&"_"&RIGHT(A515,3) -> P4_EXP3_C_A_AI_001 | U515: =IF(O515>0,P515/O515,"") | V515: =IF(P515>0,Q515/P515,"") | W515: =IF(R515<>"",R515,Q515*'Cài đặt'!$B$12) -> 0 | X515: =IF(O515>0,W515/O515*1000,"") | Y515: =IF(T515<>"",T515,INDEX('Cài đặt'!$B$20:$C$22,MATCH(I515,'Cài đặt'!$A$20:$A$22,0),IF(K515="AI tự động",1,2))) -> 4
A516: E3-P4-002 | B516: EXP3 | C516: P4 | D516: =INDEX('Page và Ngách'!$B$5:$B$10,MATCH(C516,'Page và Ngách'!$A$5:$A$10,0)) -> Revenge / Betrayal ("you'll regret it") | E516: 1 | F516: ='Cài đặt'!$B$39+E516-1 -> 46377 | G516: S2 | H516: =IF(G516="S1",'Cài đặt'!$B$7,'Cài đặt'!$B$8) -> 20:00 | I516: ='Cài đặt'!$B$32 -> Carousel | J516: ='Cài đặt'!$B$33 -> A | K516: Human nghiên cứu | L516: =C516&"_"&B516&"_"&IF(I516="Reel","R",IF(I516="Carousel","C","I"))&"_"&J516&"_"&IF(K516="AI tự động","AI","HU")&"_"&RIGHT(A516,3) -> P4_EXP3_C_A_HU_002 | U516: =IF(O516>0,P516/O516,"") | V516: =IF(P516>0,Q516/P516,"") | W516: =IF(R516<>"",R516,Q516*'Cài đặt'!$B$12) -> 0 | X516: =IF(O516>0,W516/O516*1000,"") | Y516: =IF(T516<>"",T516,INDEX('Cài đặt'!$B$20:$C$22,MATCH(I516,'Cài đặt'!$A$20:$A$22,0),IF(K516="AI tự động",1,2))) -> 25
A517: E3-P5-001 | B517: EXP3 | C517: P5 | D517: =INDEX('Page và Ngách'!$B$5:$B$10,MATCH(C517,'Page và Ngách'!$A$5:$A$10,0)) -> Mafia / Dark romance (teaser PG-13) | E517: 1 | F517: ='Cài đặt'!$B$39+E517-1 -> 46377 | G517: S1 | H517: =IF(G517="S1",'Cài đặt'!$B$7,'Cài đặt'!$B$8) -> 12:00 | I517: ='Cài đặt'!$B$32 -> Carousel | J517: ='Cài đặt'!$B$33 -> A | K517: AI tự động | L517: =C517&"_"&B517&"_"&IF(I517="Reel","R",IF(I517="Carousel","C","I"))&"_"&J517&"_"&IF(K517="AI tự động","AI","HU")&"_"&RIGHT(A517,3) -> P5_EXP3_C_A_AI_001 | U517: =IF(O517>0,P517/O517,"") | V517: =IF(P517>0,Q517/P517,"") | W517: =IF(R517<>"",R517,Q517*'Cài đặt'!$B$12) -> 0 | X517: =IF(O517>0,W517/O517*1000,"") | Y517: =IF(T517<>"",T517,INDEX('Cài đặt'!$B$20:$C$22,MATCH(I517,'Cài đặt'!$A$20:$A$22,0),IF(K517="AI tự động",1,2))) -> 4
A518: E3-P5-002 | B518: EXP3 | C518: P5 | D518: =INDEX('Page và Ngách'!$B$5:$B$10,MATCH(C518,'Page và Ngách'!$A$5:$A$10,0)) -> Mafia / Dark romance (teaser PG-13) | E518: 1 | F518: ='Cài đặt'!$B$39+E518-1 -> 46377 | G518: S2 | H518: =IF(G518="S1",'Cài đặt'!$B$7,'Cài đặt'!$B$8) -> 20:00 | I518: ='Cài đặt'!$B$32 -> Carousel | J518: ='Cài đặt'!$B$33 -> A | K518: AI tự động | L518: =C518&"_"&B518&"_"&IF(I518="Reel","R",IF(I518="Carousel","C","I"))&"_"&J518&"_"&IF(K518="AI tự động","AI","HU")&"_"&RIGHT(A518,3) -> P5_EXP3_C_A_AI_002 | U518: =IF(O518>0,P518/O518,"") | V518: =IF(P518>0,Q518/P518,"") | W518: =IF(R518<>"",R518,Q518*'Cài đặt'!$B$12) -> 0 | X518: =IF(O518>0,W518/O518*1000,"") | Y518: =IF(T518<>"",T518,INDEX('Cài đặt'!$B$20:$C$22,MATCH(I518,'Cài đặt'!$A$20:$A$22,0),IF(K518="AI tự động",1,2))) -> 4
...

Sheet Kết quả
A1: KẾT QUẢ — tự tính từ Nhật ký bài. Chỉ MỞ để chốt kết luận vào ngày cuối mỗi thí nghiệm.
A2: Đừng "ngó" rồi đổi giữa chừng: nhìn sớm dễ bị đánh lừa bởi may rủi. Mọi ô ở đây là công thức — không sửa tay.
A4: TÓM TẮT NHANH — cập nhật tự động
A5: Thí nghiệm | B5: Gợi ý theo CTR | C5: Gợi ý theo $/1.000 reach | D5: Bạn đã chốt | E5: Trạng thái / Xứng đáng?
A6: TN1 — Format | B6: =$B$18 -> (chưa có dữ liệu) | C6: =$B$19 -> (chưa có dữ liệu) | D6: ='Cài đặt'!$B$32 -> Carousel | E6: Xem bảng "Công sức có xứng đáng?" của TN1
A7: TN2 — Hook | B7: =$B$35 -> (chưa có dữ liệu) | C7: =$B$36 -> (chưa có dữ liệu) | D7: ='Cài đặt'!$B$33 -> A | E7: Chọn hook có p < ngưỡng; nếu hòa, chọn hook dễ sản xuất nhất
A8: TN3 — Cách làm | B8: =$B$45 -> (chưa có dữ liệu) | C8: =$B$46 -> (chưa có dữ liệu) | D8: — | E8: =$G$51 -> Chưa đủ dữ liệu
A11: THÍ NGHIỆM 1 — ĐỊNH DẠNG: Ảnh chữ vs Carousel vs Reel (Tuần 5–7, cùng hook A, cùng cách làm AI)
A12: Mốc so sánh = Ảnh chữ (rẻ công nhất). Hỏi: Carousel/Reel có kéo thêm click/tiền đủ bù công làm thêm không?
A13: Biến thể | B13: Số bài có dữ liệu | C13: Reach | D13: Clicks | E13: Installs | F13: Doanh thu ($) | G13: CTR | H13: Click→Install | I13: $ / 1.000 reach | J13: $ / bài | K13: Phút công | L13: z so với mốc | M13: p-value | N13: Đủ dữ liệu? | O13: Kết luận so với mốc (baseline)
